Workbook

Sheet Summary
A1: DCDC_LLC_4SBB_G474 Rev E - shortage risk, 2nd / 3rd sources (spec + footprint checked)
A2: LCSC stock read live from lcsc.com on 2026-10-20. Stock moves daily - re-check at order time. JLC basic parts may be in JLC's own SMT stock when LCSC retail shows 0.
A4: Risk | B4: Lines | C4: Rule
A5: CRITICAL | B5: =COUNTIF(Sourcing!M:M,"CRITICAL") | C5: Out of stock / not listed / < 50 boards, or a BOM error - change before ordering (same footprint)
A6: HIGH | B6: =COUNTIF(Sourcing!M:M,"HIGH") | C6: Covers < 100-300 boards, single maker, or discontinued - buy now
A7: MEDIUM | B7: =COUNTIF(Sourcing!M:M,"MEDIUM") | C7: Covers < 1,000 boards or alternates thin
A8: LOW | B8: =COUNTIF(Sourcing!M:M,"LOW") | C8: Plenty of stock and two checked alternates
A10: Check | B10: Alternates | C10: Meaning
A11: DS | B11: =COUNTIF(Sourcing!S:S,"DS")+COUNTIF(Sourcing!X:X,"DS") | C11: Checked against the datasheet: pinout vs board netlist, land pattern vs footprint, ratings
A12: EQ | B12: =COUNTIF(Sourcing!S:S,"EQ")+COUNTIF(Sourcing!X:X,"EQ") | C12: Same part number from another maker, or passive with same value / package / dielectric and equal-or-better rating
A13: CHK | B13: =COUNTIF(Sourcing!S:S,"CHK")+COUNTIF(Sourcing!X:X,"CHK") | C13: Usable; one item to confirm (see note)
A14: PCB | B14: =COUNTIF(Sourcing!S:S,"PCB")+COUNTIF(Sourcing!X:X,"PCB") | C14: Needs a PCB change - see 'PCB reserve'
A16: Packages | C16: All lines use industry-standard packages except: T2 (Pulse EP13Plus, vendor-specific) and T1 (custom PQ2620, hand-fitted). L1 1770 / L2-L3 5040 / SW1 2.54 SMD DIP / J1-J2 5.08 pluggable are de-facto standards made by many vendors.
A18: First source changed on the Rev E BOM today (all in stock, same footprints):
A19: C1235414 | B19: STM32G474RBT3 (ST) | C19: replaces C529413 STM32G474RBT6 - not listed / out of stock
A20: C503061 | B20: NCEP068N10G (NCE) | C20: replaces C503012 NCEP0160AG
A21: C2906861 | B21: FRC0402F1002TS (FOJAN) | C21: replaces C25744 0402WGF1002TCE - not listed / out of stock
A22: C20539426 | B22: TCC0402X5R105K500AT (CCTC) | C22: replaces C52923 CL05A105KA5NQNC - not listed / out of stock
A23: C2907006 | B23: FRC0603F2R20TS (FOJAN) | C23: replaces C22939 0603WAF220KT5E - not listed / out of stock
A24: C2929994 | B24: FRC0402F22R0TS (FOJAN) | C24: replaces C25092 0402WGF220JTCE - not listed / out of stock
A25: C844452 | B25: TNPW040210K0BEED (VISHAY) | C25: replaces C190095 RT0402BRD0710KL - not listed / out of stock
A26: C85833 | B26: BLM18KG601SN1D (muRata) | C26: replaces C1002 GZ1608D601TF - not listed / out of stock
A27: C167974 | B27: FNR5040S470MT (cjiang) | C27: replaces C86617 SWPA5040S470MT - not listed / out of stock
A28: C2233314 | B28: C0805C473F3GECAUTO (KEMET) | C28: replaces C53134 CL21B473KBCNNNC
A29: C2904236 | B29: HoJLR2512-3W-4mR-1% (Milliohm) | C29: replaces C500738 LR2512D-3W-4mR-1%
A30: C2482 | B30: SS110 (MDD(Microdiode Semiconductor)) | C30: replaces C224219 SS110
A31: C307331 | B31: CL05B104KB54PNC | C31: now also used for the 22 x 100 nF that were on C1525 (out of stock)
A33: Buy now / watch:
A34: C249664 | B34: C1,C11,C60 | C34: 175 pcs, 3 per board (58 boards). ChengTao RVE1J470M1010 is an exact 2nd source.
A35: C49308184 | B35: L1 | C35: 120 pcs. Buy now. SMMS1770-220M / SLO1770C (both 23 A sat, 1770 body) - SOREDE 16 A part dropped.
A36: C5718384 | B36: T2 | C36: 102 pcs, single maker (Pulse). Buy now. Backup needs the T2 jumper option (PA3855.005NLT in series).
A37: C141980 | B37: U2,U3,U10 | C37: 338 pcs, 3 per board. UCC27211AQDDARQ1 (same DDA) / UCC27211DR (SOIC-8, no pad).
A39: Not on LCSC | B39: T1 | C39: Custom PQ2620 transformer - the only part not orderable from LCSC
A40: Extra to order | B40: J1, J2 plugs | C40: Kefa KF2EDGK-5.08-2P-AA (C440880), 2 per board - the cable-side plugs; JP1 needs one 2.54 mm jumper cap

Sheet Sourcing
A1: # | B1: Designators | C1: Qty / board | D1: Description | E1: Footprint | F1: Package type | G1: Primary MPN | H1: Manufacturer | I1: LCSC # | J1: LCSC stock today | K1: Boards covered | L1: Price from (USD) | M1: Risk | N1: Action | O1: Use as primary (same footprint) | P1: 2nd source | Q1: 2nd LCSC # | R1: 2nd stock | S1: 2nd check | T1: 2nd spec / fit note | U1: 3rd source | V1: 3rd LCSC # | W1: 3rd stock | X1: 3rd check | Y1: 3rd spec / fit note | Z1: Sources with stock for 100 boards
A2: 1 | B2: C1,C11,C60 | C2: 3 | D2: 47u 63V | E2: CP_Elec_10x10.5 | F2: Standard (SMD alu 10x10.5) | G2: VEJ470M1JTR-1010 | H2: Lelon | I2: C249664 | J2: 175 | K2: =IF(ISNUMBER(J2),INT(J2/C2),0) | L2: 0.0875 | M2: HIGH | N2: 175 pcs, 3 per board (58 boards). ChengTao RVE1J470M1010 is an exact 2nd source. | P2: RVE1J470M1010 (ChengTao) | Q2: C46527630 | R2: 350 | S2: EQ | T2: ChengTao RVE1J470M1010: 47 uF 63 V 10x10.5, 105 C | U2: RVT63V100M10X10 (JIERR) | V2: C51953411 | W2: 24990 | X2: CHK | Y2: JIERR 100 uF 63 V 10x10.5: same can, more C -> check F1 inrush | Z2: =IF(ISNUMBER(J2),IF(J2>=100*C2,1,0),0)+IF(ISNUMBER(R2),IF(R2>=100*C2,1,0),0)+IF(ISNUMBER(W2),IF(W2>=100*C2,1,0),0)
A3: 28 | B3: L1 | C3: 1 | D3: PSPMAA1770-220M-CGP | E3: L_Bourns_SRP1770TA_16.9x16.9mm | F3: De-facto standard (many makers) (1770 molded) | G3: PSPMAA1770-220M-CGP | H3: PROD Tech | I3: C49308184 | J3: 120 | K3: =IF(ISNUMBER(J3),INT(J3/C3),0) | L3: 0.8544 | M3: HIGH | N3: 120 pcs. Buy now. SMMS1770-220M / SLO1770C (both 23 A sat, 1770 body) - SOREDE 16 A part dropped. | P3: SMMS1770-220M (Shun Xiang Nuo) | Q3: C2976969 | R3: 961 | S3: CHK | T3: Shun Xiang Nuo SMMS1770-220M 22 uH, Isat 23 A, 17.5x17.2 - same 1770 body; confirm land drawing | U3: SLO1770C220MTT (Sunltech) | V3: C48996578 | W3: 150 | X3: DS | Y3: Sunltech SLO1770C220MTT 22 uH, Isat 23 A - land 3.5x12.8 / gap 11.2 fits the SRP1770 footprint | Z3: =IF(ISNUMBER(J3),IF(J3>=100*C3,1,0),0)+IF(ISNUMBER(R3),IF(R3>=100*C3,1,0),0)+IF(ISNUMBER(W3),IF(W3>=100*C3,1,0),0)
A4: 68 | B4: T2 | C4: 1 | D4: PA3855.006NLT | E4: TX_PA3855_EP13_10P | F4: Vendor-specific (Pulse EP13Plus) | G4: PA3855.006NLT | H4: PULSE | I4: C5718384 | J4: 102 | K4: =IF(ISNUMBER(J4),INT(J4/C4),0) | L4: 1.2828 | M4: HIGH | N4: 102 pcs, single maker (Pulse). Buy now. Backup needs the T2 jumper option (PA3855.005NLT in series). | P4: PA3855.005NLT (PULSE) | Q4: C17526143 | R4: 520 | S4: PCB | T4: Pulse PA3855.005NLT: same EP13 footprint and primary, secondaries must be in SERIES - needs the T2 jumper option | Y4: Custom-wound EP13 to the same pinout from a local winder (no PCB change) | Z4: =IF(ISNUMBER(J4),IF(J4>=100*C4,1,0),0)+IF(ISNUMBER(R4),IF(R4>=100*C4,1,0),0)+IF(ISNUMBER(W4),IF(W4>=100*C4,1,0),0)
A5: 70 | B5: U2,U3,U10 | C5: 3 | D5: UCC27211DDAR | E5: SOIC-8-1EP_3.9x4.9mm_P1.27mm_EP2.41x3.3mm | F5: Standard (SOIC-8 PowerPAD) | G5: UCC27211DDAR | H5: TI | I5: C141980 | J5: 338 | K5: =IF(ISNUMBER(J5),INT(J5/C5),0) | L5: 1.4619 | M5: HIGH | N5: 338 pcs, 3 per board. UCC27211AQDDARQ1 (same DDA) / UCC27211DR (SOIC-8, no pad). | P5: UCC27211AQDDARQ1 (TI) | Q5: C485921 | R5: 755 | S5: DS | T5: TI UCC27211AQDDARQ1 (same DDA package and pinout) | U5: UCC27211DR (TI) | V5: C2871979 | W5: 2138 | X5: DS | Y5: TI UCC27211DR SOIC-8 (no pad): same pinout; pad 9 left unsoldered - remove its paste for this build | Z5: =IF(ISNUMBER(J5),IF(J5>=100*C5,1,0),0)+IF(ISNUMBER(R5),IF(R5>=100*C5,1,0),0)+IF(ISNUMBER(W5),IF(W5>=100*C5,1,0),0)
A6: 19 | B6: CR1,CR2,CR3,CR4,CR5,CR6 | C6: 6 | D6: 100n 100V C0G | E6: C_1206_3216Metric | F6: Standard (1206) | G6: C1206N104J101T | H6: IHHEC | I6: C2940749 | J6: 1802 | K6: =IF(ISNUMBER(J6),INT(J6/C6),0) | L6: 0.1817 | M6: MEDIUM | N6: 902 pcs, 6 per board (150 boards). Murata / TDK 1206 C0G 100 V are verified 2nd/3rd (CCTC/HRE 'M3L' parts dropped: not C0G). | P6: GRM31C5C2A104JA01L (muRata) | Q6: C405303 | R6: 7815 | S6: EQ | T6: Murata GRM31C5C2A104JA01L 100 nF C0G 5 % 100 V 1206 | U6: C3216C0G2A104JT000E (TDK) | V6: C338111 | W6: 1350 | X6: EQ | Y6: TDK C3216C0G2A104JT000E 100 nF C0G 5 % 100 V 1206 | Z6: =IF(ISNUMBER(J6),IF(J6>=100*C6,1,0),0)+IF(ISNUMBER(R6),IF(R6>=100*C6,1,0),0)+IF(ISNUMBER(W6),IF(W6>=100*C6,1,0),0)
A7: 26 | B7: F1 | C7: 1 | D7: 0458007.DR | E7: Fuse_1206_3216Metric | F7: Standard (1206 fuse) | G7: 0458007.DR | H7: Littelfuse | I7: C206980 | J7: 765 | K7: =IF(ISNUMBER(J7),INT(J7/C7),0) | L7: 0.4845 | M7: MEDIUM | N7: 765 pcs. Reomax R12.000.7 verified as 2nd source. | P7: R12.000.7 (Reomax) | Q7: C5383192 | R7: 2710 | S7: DS | T7: Reomax R12.000.7 7 A 63 V DC 1206 | U7: 3413.0326.11 (SCHURTER) | V7: C3165071 | W7: 40 | X7: EQ | Y7: Schurter 3413.0326.11 7 A 63 V 1206 (low stock) | Z7: =IF(ISNUMBER(J7),IF(J7>=100*C7,1,0),0)+IF(ISNUMBER(R7),IF(R7>=100*C7,1,0),0)+IF(ISNUMBER(W7),IF(W7>=100*C7,1,0),0)
A8: 30 | B8: Q1,Q4 | C8: 2 | D8: NCEP0140AG | E8: TDSON-8-1 | F8: Standard (DFN5x6 / PowerPAK SO-8) | G8: NCEP0140AG | H8: NCE | I8: C503009 | J8: 4695 | K8: =IF(ISNUMBER(J8),INT(J8/C8),0) | L8: 0.286 | M8: MEDIUM | N8: 4,695 pcs (2,300 boards). NCE alternates have 2x the gate charge - fine, but check Q1/Q4 temperature on the bench if used. | P8: NCEP095N10AG (NCE) | Q8: C2686677 | R8: 645 | S8: CHK | T8: NCE NCEP095N10AG 100 V 12 mOhm: Qg 54 nC vs 26 nC - more gate/switching loss in the hard-switched Q1/Q4, check temp | U8: NCEP068N10G (NCE) | V8: C503061 | W8: 7577 | X8: CHK | Y8: NCE NCEP068N10G 100 V 6.1 mOhm: Qg 60 nC vs 26 nC - same check | Z8: =IF(ISNUMBER(J8),IF(J8>=100*C8,1,0),0)+IF(ISNUMBER(R8),IF(R8>=100*C8,1,0),0)+IF(ISNUMBER(W8),IF(W8>=100*C8,1,0),0)
A9: 35 | B9: Q11 | C9: 1 | D9: FDN86246 | E9: SOT-23 | F9: Standard (SOT-23) | G9: FDN86246 | H9: onsemi | I9: C891118 | J9: 1606 | K9: =IF(ISNUMBER(J9),INT(J9/C9),0) | L9: 0.6163 | M9: MEDIUM | N9: 1,606 pcs. JSMSEMI FDN86246 / HSS2N15 (150 V) - same SOT-23 pinout. | P9: FDN86246 (JSMSEMI) | Q9: C7421706 | R9: 4035 | S9: EQ | T9: JSMSEMI FDN86246 (same part no.) 150 V | U9: HSS2N15 (HUASHUO) | V9: C2987707 | W9: 6090 | X9: EQ | Y9: HUASHUO HSS2N15 150 V 1.8 A | Z9: =IF(ISNUMBER(J9),IF(J9>=100*C9,1,0),0)+IF(ISNUMBER(R9),IF(R9>=100*C9,1,0),0)+IF(ISNUMBER(W9),IF(W9>=100*C9,1,0),0)
A10: 51 | B10: R81 | C10: 1 | D10: 191k 0.1% | E10: R_1206_3216Metric | F10: Standard (1206) | G10: RT1206BRD07191KL | H10: YAGEO | I10: C870479 | J10: 4755 | K10: =IF(ISNUMBER(J10),INT(J10/C10),0) | L10: 0.0506 | M10: MEDIUM | N10: Single LCSC source (4,755 pcs, 1 per board). Other makers only at Digikey/Mouser. | T10: No other 191k 0.1 % 1206 in stock on LCSC (Panasonic ERA-8AEB1913V / Vishay TNPW1206191KBEEA at Digikey/Mouser) | Y10: none in stock on LCSC | Z10: =IF(ISNUMBER(J10),IF(J10>=100*C10,1,0),0)+IF(ISNUMBER(R10),IF(R10>=100*C10,1,0),0)+IF(ISNUMBER(W10),IF(W10>=100*C10,1,0),0)
A11: 75 | B11: U9 | C11: 1 | D11: CA-IS3062VW | E11: SOIC-16W_7.5x10.3mm_P1.27mm | F11: Standard (SOIC-16W) | G11: CA-IS3062VW | H11: Chipanalog | I11: C5338808 | J11: 4777 | K11: =IF(ISNUMBER(J11),INT(J11/C11),0) | L11: 2.16 | M11: MEDIUM | N11: 4,777 pcs but Chipanalog only (integrated isolated DC-DC). Backup ISO1042DW + B0505S needs the U9 reserve option. | P11: ISO1042QDWRQ1 (TI) | Q11: C2671569 | R11: 2231 | S11: PCB | T11: TI ISO1042QDWRQ1 fits the U9 footprint (pins 2-16 match) but needs pin 1 = 3.3 V and an external isolated 5 V (B0505S module) - U9 reserve option | U11: ISO1042DWR (TI) | V11: C1848126 | W11: 270 | X11: PCB | Y11: TI ISO1042DWR - same as above | Z11: =IF(ISNUMBER(J11),IF(J11>=100*C11,1,0),0)+IF(ISNUMBER(R11),IF(R11>=100*C11,1,0),0)+IF(ISNUMBER(W11),IF(W11>=100*C11,1,0),0)
A12: 77 | B12: U12 | C12: 1 | D12: CA-IS3742LW | E12: SOIC-16W_7.5x10.3mm_P1.27mm | F12: Standard (SOIC-16W) | G12: CA-IS3742LW | H12: Chipanalog | I12: C4944981 | J12: 2320 | K12: =IF(ISNUMBER(J12),INT(J12/C12),0) | L12: 0.46 | M12: MEDIUM | N12: 2,320 pcs; default-LOW wide-body alternates exist but have low stock (TI 139, YLPTEC 90). | P12: ISO7742FDWR (TI) | Q12: C2862403 | R12: 139 | S12: DS | T12: TI ISO7742FDWR: same pinout, default LOW (F) like CA-IS3742L - low stock | U12: ISO7742W0-Y (YLPTEC) | V12: C53446650 | W12: 90 | X12: DS | Y12: YLPTEC ISO7742W0-Y: wide body, default LOW ('0') - low stock (do NOT use the N0 narrow-body part) | Z12: =IF(ISNUMBER(J12),IF(J12>=100*C12,1,0),0)+IF(ISNUMBER(R12),IF(R12>=100*C12,1,0),0)+IF(ISNUMBER(W12),IF(W12>=100*C12,1,0),0)
A13: 84 | B13: U1 | C13: 1 | D13: STM32G474RBT3 (hand-soldered) | E13: LQFP-64_10x10mm_P0.5mm | F13: Standard (LQFP-64) | G13: STM32G474RBT3 | H13: ST | I13: C1235414 | J13: 564 | K13: =IF(ISNUMBER(J13),INT(J13/C13),0) | L13: 2.9236 | M13: MEDIUM | N13: Primary covers the build; alternates thin - watch. | P13: STM32G474RET6 (ST) | Q13: C521608 | R13: 12 | S13: EQ | T13: ST STM32G474RET6 (512 KB, same pinout; 12 pcs) | Y13: none in stock on LCSC | Z13: =IF(ISNUMBER(J13),IF(J13>=100*C13,1,0),0)+IF(ISNUMBER(R13),IF(R13>=100*C13,1,0),0)+IF(ISNUMBER(W13),IF(W13>=100*C13,1,0),0)
A14: 89 | B14: J7 | C14: 1 | D14: HX PZ1.27-2x5P TP (hand-soldered) | E14: PinHeader_2x05_P1.27mm_Vertical_SMD | F14: Standard (1.27 SMD header) | G14: HX PZ1.27-2x5P TP | H14: hanxia | I14: C41376037 | J14: 40345 | K14: =IF(ISNUMBER(J14),INT(J14/C14),0) | M14: MEDIUM | N14: Primary covers the build; alternates thin - watch. | T14: Samtec FTSH-105-01-L-DV-K or any 2x5 1.27 mm SMD header | Y14: none in stock on LCSC | Z14: =IF(ISNUMBER(J14),IF(J14>=100*C14,1,0),0)+IF(ISNUMBER(R14),IF(R14>=100*C14,1,0),0)+IF(ISNUMBER(W14),IF(W14>=100*C14,1,0),0)
A15: 2 | B15: C2,C3,C4,C5,C7,C8,C9,C10,C61,C62,C63,C70,C95 | C15: 13 | D15: 2.2u 100V X7R | E15: C_1210_3225Metric | F15: Standard (1210) | G15: FS32X225K101EGG | H15: PSA | I15: C153036 | J15: 261555 | K15: =IF(ISNUMBER(J15),INT(J15/C15),0) | L15: 0.0476 | M15: LOW | N15: Stock fine; 2nd/3rd checked. | P15: GRM32ER72A225KA35L (muRata) | Q15: C86054 | R15: 25205 | S15: EQ | T15: Murata GRM32ER72A225KA35L 2.2 uF 100 V X7R 1210 | U15: HMK325B7225KN-T (Taiyo Yuden) | V15: C92775 | W15: 30780 | X15: EQ | Y15: Taiyo Yuden HMK325B7225KN-T 2.2 uF 100 V X7R 1210 | Z15: =IF(ISNUMBER(J15),IF(J15>=100*C15,1,0),0)+IF(ISNUMBER(R15),IF(R15>=100*C15,1,0),0)+IF(ISNUMBER(W15),IF(W15>=100*C15,1,0),0)
A16: 3 | B16: C6,C12 | C16: 2 | D16: 100n 100V X7R | E16: C_0603_1608Metric | F16: Standard (0603) | G16: 0603B104K101NT | H16: FH | I16: C88219 | J16: 1977150 | K16: =IF(ISNUMBER(J16),INT(J16/C16),0) | L16: 0.0058 | M16: LOW | N16: Stock fine; 2nd/3rd checked. | P16: CC0603KRX7R0BB104 (YAGEO) | Q16: C113803 | R16: 328150 | S16: EQ | T16: Yageo CC0603KRX7R0BB104 100 V X7R | U16: AM03B104K101NT (FH) | V16: C42959888 | W16: 4980 | X16: EQ | Y16: FH AM03B104K101NT 100 V X7R | Z16: =IF(ISNUMBER(J16),IF(J16>=100*C16,1,0),0)+IF(ISNUMBER(R16),IF(R16>=100*C16,1,0),0)+IF(ISNUMBER(W16),IF(W16>=100*C16,1,0),0)
A17: 4 | B17: C15,C18,C67 | C17: 3 | D17: 100n 25V X7R | E17: C_0603_1608Metric | F17: Standard (0603) | G17: CC0603KRX7R9BB104 | H17: YAGEO | I17: C14663 | J17: 6739100 | K17: =IF(ISNUMBER(J17),INT(J17/C17),0) | L17: 0.0067 | M17: LOW | N17: Stock fine; 2nd/3rd checked. | P17: 0603B104K500CT (Walsin) | Q17: C314282 | R17: 835700 | S17: EQ | T17: Walsin 0603B104K500CT 50 V X7R | U17: VJ0603Y104KXACW1BC (VISHAY) | V17: C161854 | W17: 13120 | X17: EQ | Y17: Vishay VJ0603Y104KXACW1BC 50 V X7R | Z17: =IF(ISNUMBER(J17),IF(J17>=100*C17,1,0),0)+IF(ISNUMBER(R17),IF(R17>=100*C17,1,0),0)+IF(ISNUMBER(W17),IF(W17>=100*C17,1,0),0)
A18: 5 | B18: C16,C19,C68,C69,C88 | C18: 5 | D18: 1u 25V X7R | E18: C_0603_1608Metric | F18: Standard (0603) | G18: CL10A105KB8NNNC | H18: Samsung Electro-Mechanics | I18: C15849 | J18: 2731000 | K18: =IF(ISNUMBER(J18),INT(J18/C18),0) | L18: 0.0087 | M18: LOW | N18: Stock fine; 2nd/3rd checked. | P18: 0603X105K500NT (FH) | Q18: C157684 | R18: 774900 | S18: EQ | T18: FH 0603X105K500NT 1 uF 50 V X5R | U18: CC0603KRX5R9BB105 (YAGEO) | V18: C128624 | W18: 23100 | X18: EQ | Y18: Yageo CC0603KRX5R9BB105 1 uF 50 V X5R | Z18: =IF(ISNUMBER(J18),IF(J18>=100*C18,1,0),0)+IF(ISNUMBER(R18),IF(R18>=100*C18,1,0),0)+IF(ISNUMBER(W18),IF(W18>=100*C18,1,0),0)
A19: 6 | B19: C17,C20,C22,C23,C71,C89,C29,C30,C31,C32,C33,C34,C37,C40,C43,C44,C46,C48,C50,C53,C54,C75,C77,C80,C83,C84,C90,C99 | C19: 28 | D19: 100n 25V | E19: C_0402_1005Metric | F19: Standard (0402) | G19: CL05B104KB54PNC | H19: Samsung Electro-Mechanics | I19: C307331 | J19: 2343800 | K19: =IF(ISNUMBER(J19),INT(J19/C19),0) | L19: 0.0049 | M19: LOW | N19: Stock fine; 2nd/3rd checked. | P19: CC0402KRX7R9BB104 (YAGEO) | Q19: C131394 | R19: 4590850 | S19: EQ | T19: Yageo CC0402KRX7R9BB104 50 V X7R | U19: 0402B104K500NT (FH) | V19: C110251 | W19: 1825760 | X19: EQ | Y19: FH 0402B104K500NT 50 V X7R | Z19: =IF(ISNUMBER(J19),IF(J19>=100*C19,1,0),0)+IF(ISNUMBER(R19),IF(R19>=100*C19,1,0),0)+IF(ISNUMBER(W19),IF(W19>=100*C19,1,0),0)
A20: 7 | B20: C21,C24,C25,C26,C72,C96,C97,C49,C52 | C20: 9 | D20: 10u 25V X5R | E20: C_0805_2012Metric | F20: Standard (0805) | G20: CL21A106KAYNNNE | H20: Samsung Electro-Mechanics | I20: C15850 | J20: 3082660 | K20: =IF(ISNUMBER(J20),INT(J20/C20),0) | L20: 0.0528 | M20: LOW | N20: Stock fine; 2nd/3rd checked. | P20: TCC0805X5R106K350FT (CCTC) | Q20: C18185754 | R20: 100165 | S20: EQ | T20: CCTC TCC0805X5R106K350FT 10 uF 35 V X5R | U20: GRM21BR6YA106KE43L (muRata) | V20: C162422 | W20: 99525 | X20: EQ | Y20: Murata GRM21BR6YA106KE43L 10 uF 35 V X5R | Z20: =IF(ISNUMBER(J20),IF(J20>=100*C20,1,0),0)+IF(ISNUMBER(R20),IF(R20>=100*C20,1,0),0)+IF(ISNUMBER(W20),IF(W20>=100*C20,1,0),0)
A21: 8 | B21: C27,C73 | C21: 2 | D21: 22u 10V X5R | E21: C_0805_2012Metric | F21: Standard (0805) | G21: CL21A226MAQNNNE | H21: Samsung Electro-Mechanics | I21: C45783 | J21: 100080 | K21: =IF(ISNUMBER(J21),INT(J21/C21),0) | L21: 0.1061 | M21: LOW | N21: Stock fine; 2nd/3rd checked. | P21: TCC0805X5R226M250FT (CCTC) | Q21: C20416420 | R21: 131690 | S21: EQ | T21: CCTC TCC0805X5R226M250FT 22 uF 25 V | U21: 0805X226M250NT (FH) | V21: C129303 | W21: 85780 | X21: EQ | Y21: FH 0805X226M250NT 22 uF 25 V | Z21: =IF(ISNUMBER(J21),IF(J21>=100*C21,1,0),0)+IF(ISNUMBER(R21),IF(R21>=100*C21,1,0),0)+IF(ISNUMBER(W21),IF(W21>=100*C21,1,0),0)
A22: 9 | B22: C28,C36,C51,C86 | C22: 4 | D22: 1u 10V | E22: C_0402_1005Metric | F22: Standard (0402) | G22: TCC0402X5R105K500AT | H22: CCTC | I22: C20539426 | J22: 179400 | K22: =IF(ISNUMBER(J22),INT(J22/C22),0) | L22: 0.0099 | M22: LOW | N22: Stock fine; 2nd/3rd checked. | P22: GRM155R61H105KE05D (muRata) | Q22: C1518208 | R22: 32180 | S22: EQ | T22: Murata GRM155R61H105KE05D 1 uF 50 V X5R | Y22: none in stock on LCSC | Z22: =IF(ISNUMBER(J22),IF(J22>=100*C22,1,0),0)+IF(ISNUMBER(R22),IF(R22>=100*C22,1,0),0)+IF(ISNUMBER(W22),IF(W22>=100*C22,1,0),0)
A23: 10 | B23: C35 | C23: 1 | D23: 4.7u 10V | E23: C_0603_1608Metric | F23: Standard (0603) | G23: CL10A475KO8NNNC | H23: Samsung Electro-Mechanics | I23: C19666 | J23: 584680 | K23: =IF(ISNUMBER(J23),INT(J23/C23),0) | L23: 0.0114 | M23: LOW | N23: Stock fine; 2nd/3rd checked. | P23: EMK107ABJ475KA-T (Taiyo Yuden) | Q23: C92758 | R23: 157460 | S23: EQ | T23: Taiyo Yuden EMK107ABJ475KA-T 16 V X5R | U23: GRM188R61E475KE11D (muRata) | V23: C90057 | W23: 106410 | X23: EQ | Y23: Murata GRM188R61E475KE11D 25 V X5R | Z23: =IF(ISNUMBER(J23),IF(J23>=100*C23,1,0),0)+IF(ISNUMBER(R23),IF(R23>=100*C23,1,0),0)+IF(ISNUMBER(W23),IF(W23>=100*C23,1,0),0)
A24: 11 | B24: C38,C39 | C24: 2 | D24: 12p C0G | E24: C_0402_1005Metric | F24: Standard (0402) | G24: 0402CG120J500NT | H24: FH | I24: C1547 | J24: 1236600 | K24: =IF(ISNUMBER(J24),INT(J24/C24),0) | L24: 0.0013 | M24: LOW | N24: Stock fine; 2nd/3rd checked. | P24: 0402CG120F500NT (FH) | Q24: C182477 | R24: 145100 | S24: EQ | T24: FH 0402CG120F500NT 12 pF C0G 1 % | U24: AM02CG120J500NT (FH) | V24: C49238110 | W24: 6900 | X24: EQ | Y24: FH AM02CG120J500NT 12 pF C0G | Z24: =IF(ISNUMBER(J24),IF(J24>=100*C24,1,0),0)+IF(ISNUMBER(R24),IF(R24>=100*C24,1,0),0)+IF(ISNUMBER(W24),IF(W24>=100*C24,1,0),0)
A25: 12 | B25: C41,C42,C79,C91,C92 | C25: 5 | D25: 1n C0G | E25: C_0402_1005Metric | F25: Standard (0402) | G25: CC0402JRNPO9BN102 | H25: YAGEO | I25: C113780 | J25: 60500 | K25: =IF(ISNUMBER(J25),INT(J25/C25),0) | L25: 0.0096 | M25: LOW | N25: Stock fine; 2nd/3rd checked. | P25: 0402N102J500CT (Walsin) | Q25: C237166 | R25: 158300 | S25: EQ | T25: Walsin 0402N102J500CT 1 nF NP0 | U25: AC0402JRNPO9BN102 (YAGEO) | V25: C427014 | W25: 12750 | X25: EQ | Y25: Yageo AC0402JRNPO9BN102 1 nF NP0 | Z25: =IF(ISNUMBER(J25),IF(J25>=100*C25,1,0),0)+IF(ISNUMBER(R25),IF(R25>=100*C25,1,0),0)+IF(ISNUMBER(W25),IF(W25>=100*C25,1,0),0)
A26: 13 | B26: C45 | C26: 1 | D26: 470p C0G | E26: C_0402_1005Metric | F26: Standard (0402) | G26: CC0402JRNPO9BN471 | H26: YAGEO | I26: C106259 | J26: 349500 | K26: =IF(ISNUMBER(J26),INT(J26/C26),0) | L26: 0.0021 | M26: LOW | N26: Stock fine; 2nd/3rd checked. | P26: 0402N471J500CT (Walsin) | Q26: C295986 | R26: 74200 | S26: EQ | T26: Walsin 0402N471J500CT 470 pF NP0 | U26: CC0402GRNPO9BN471 (YAGEO) | V26: C541429 | W26: 2700 | X26: EQ | Y26: Yageo CC0402GRNPO9BN471 470 pF NP0 2 % | Z26: =IF(ISNUMBER(J26),IF(J26>=100*C26,1,0),0)+IF(ISNUMBER(R26),IF(R26>=100*C26,1,0),0)+IF(ISNUMBER(W26),IF(W26>=100*C26,1,0),0)
A27: 14 | B27: C47 | C27: 1 | D27: 10n C0G | E27: C_0402_1005Metric | F27: Standard (0402) | G27: GRM1555C1H103JE01D | H27: muRata | I27: C22400107 | J27: 52755 | K27: =IF(ISNUMBER(J27),INT(J27/C27),0) | L27: 0.06 | M27: LOW | N27: Stock fine; 2nd/3rd checked. | P27: GRM1555C1E103JE01D (muRata) | Q27: C3855387 | R27: 65320 | S27: EQ | T27: Murata GRM1555C1E103JE01D C0G 25 V (C47 sits on a 3.3 V ADC node) | U27: CGA0402C0G103J250GT (HRE) | V27: C36911359 | W27: 10855 | X27: EQ | Y27: HRE CGA0402C0G103J250GT C0G 25 V | Z27: =IF(ISNUMBER(J27),IF(J27>=100*C27,1,0),0)+IF(ISNUMBER(R27),IF(R27>=100*C27,1,0),0)+IF(ISNUMBER(W27),IF(W27>=100*C27,1,0),0)
A28: 15 | B28: C55 | C28: 1 | D28: 4.7n | E28: C_0603_1608Metric | F28: Standard (0603) | G28: 0603B472K500NT | H28: FH | I28: C53987 | J28: 309050 | K28: =IF(ISNUMBER(J28),INT(J28/C28),0) | L28: 0.0027 | M28: LOW | N28: Stock fine; 2nd/3rd checked. | P28: 0603B472K101NT (FH) | Q28: C12164 | R28: 14250 | S28: EQ | T28: FH 0603B472K101NT 100 V X7R | U28: 0603B472J500NT (FH) | V28: C168956 | W28: 9300 | X28: EQ | Y28: FH 0603B472J500NT 50 V X7R | Z28: =IF(ISNUMBER(J28),IF(J28>=100*C28,1,0),0)+IF(ISNUMBER(R28),IF(R28>=100*C28,1,0),0)+IF(ISNUMBER(W28),IF(W28>=100*C28,1,0),0)
A29: 16 | B29: C81,C93 | C29: 2 | D29: 220p C0G | E29: C_0402_1005Metric | F29: Standard (0402) | G29: CC0402JRNPO9BN221 | H29: YAGEO | I29: C107001 | J29: 483000 | K29: =IF(ISNUMBER(J29),INT(J29/C29),0) | L29: 0.0024 | M29: LOW | N29: Stock fine; 2nd/3rd checked. | P29: 0402N221J500CT (Walsin) | Q29: C301973 | R29: 33400 | S29: EQ | T29: Walsin 0402N221J500CT 220 pF NP0 | U29: CC0402GRNPO9BN221 (YAGEO) | V29: C541425 | W29: 27400 | X29: EQ | Y29: Yageo CC0402GRNPO9BN221 220 pF NP0 | Z29: =IF(ISNUMBER(J29),IF(J29>=100*C29,1,0),0)+IF(ISNUMBER(R29),IF(R29>=100*C29,1,0),0)+IF(ISNUMBER(W29),IF(W29>=100*C29,1,0),0)
A30: 17 | B30: C82 | C30: 1 | D30: C0805C473F3GECAUTO | E30: C_0805_2012Metric | F30: Standard (0805) | G30: C0805C473F3GECAUTO | H30: KEMET | I30: C2233314 | J30: 2403 | K30: =IF(ISNUMBER(J30),INT(J30/C30),0) | L30: 0.4834 | M30: LOW | N30: Stock fine; 2nd/3rd checked. | P30: C0805C473K3GECTU (KEMET) | Q30: C22409143 | R30: 830 | S30: DS | T30: KEMET C0805C473K3GECTU 47 nF C0G 10 % 25 V | U30: CL21B473KBCNNNC (Samsung Electro-Mechanics) | V30: C53134 | W30: 23600 | X30: EQ | Y30: previous primary (low / no stock) | Z30: =IF(ISNUMBER(J30),IF(J30>=100*C30,1,0),0)+IF(ISNUMBER(R30),IF(R30>=100*C30,1,0),0)+IF(ISNUMBER(W30),IF(W30>=100*C30,1,0),0)
A31: 18 | B31: C94 | C31: 1 | D31: 4.7n 100V X7R | E31: C_0603_1608Metric | F31: Standard (0603) | G31: CC0603KRX7R0BB472 | H31: YAGEO | I31: C115052 | J31: 80950 | K31: =IF(ISNUMBER(J31),INT(J31/C31),0) | L31: 0.008 | M31: LOW | N31: Stock fine; 2nd/3rd checked. | P31: 0603B472K101NT (FH) | Q31: C12164 | R31: 14250 | S31: EQ | T31: FH 0603B472K101NT 100 V X7R | U31: 0603B472K101CT (Walsin) | V31: C152940 | W31: 2600 | X31: EQ | Y31: Walsin 0603B472K101CT 100 V X7R | Z31: =IF(ISNUMBER(J31),IF(J31>=100*C31,1,0),0)+IF(ISNUMBER(R31),IF(R31>=100*C31,1,0),0)+IF(ISNUMBER(W31),IF(W31>=100*C31,1,0),0)
A32: 20 | B32: D1 | C32: 1 | D32: SMBJ51A | E32: D_SMB | F32: Standard (SMB) | G32: SMBJ51A | H32: OTW | I32: C20883337 | J32: 9260 | K32: =IF(ISNUMBER(J32),INT(J32/C32),0) | L32: 0.0163 | M32: LOW | N32: Stock fine; 2nd/3rd checked. | P32: SMBJ51A (Littelfuse) | Q32: C1973217 | R32: 7885 | S32: EQ | T32: Littelfuse SMBJ51A | U32: SMBJ51A (RUILON) | V32: C10225 | W32: 2665 | X32: EQ | Y32: RUILON SMBJ51A | Z32: =IF(ISNUMBER(J32),IF(J32>=100*C32,1,0),0)+IF(ISNUMBER(R32),IF(R32>=100*C32,1,0),0)+IF(ISNUMBER(W32),IF(W32>=100*C32,1,0),0)
A33: 21 | B33: D2,D6,D8,D9 | C33: 4 | D33: SS110 | E33: D_SMA | F33: Standard (SMA) | G33: SS110 | H33: MDD(Microdiode Semiconductor) | I33: C2482 | J33: 163400 | K33: =IF(ISNUMBER(J33),INT(J33/C33),0) | L33: 0.01 | M33: LOW | N33: Stock fine; 2nd/3rd checked. | P33: STPS1H100A (ST) | Q33: C165701 | R33: 18455 | S33: EQ | T33: ST STPS1H100A 100 V 1 A SMA (lower leakage) | U33: SS110 (Guangdong Hottech) | V33: C224219 | W33: 1360 | X33: EQ | Y33: previous primary (low / no stock) | Z33: =IF(ISNUMBER(J33),IF(J33>=100*C33,1,0),0)+IF(ISNUMBER(R33),IF(R33>=100*C33,1,0),0)+IF(ISNUMBER(W33),IF(W33>=100*C33,1,0),0)
A34: 22 | B34: D3 | C34: 1 | D34: NUP2105LT1G | E34: SOT-23 | F34: Standard (SOT-23) | G34: NUP2105LT1G | H34: onsemi | I34: C14486 | J34: 119530 | K34: =IF(ISNUMBER(J34),INT(J34/C34),0) | L34: 0.0381 | M34: LOW | N34: Stock fine; 2nd/3rd checked. | P34: NUP2105LT1G (GOODWORK) | Q34: C21713988 | R34: 68040 | S34: EQ | T34: GOODWORK NUP2105LT1G (same part no., same pinout 1=CAN 2=CAN 3=GND) | U34: NUP2105L (DOWO) | V34: C284104 | W34: 57270 | X34: EQ | Y34: DOWO NUP2105L | Z34: =IF(ISNUMBER(J34),IF(J34>=100*C34,1,0),0)+IF(ISNUMBER(R34),IF(R34>=100*C34,1,0),0)+IF(ISNUMBER(W34),IF(W34>=100*C34,1,0),0)
... A36: 24 | B36: D5 | C36: 1 | D36: RED FAULT | E36: LED_0603_1608Metric | F36: Standard (0603 LED) | G36: KT-0603R | H36: Hubei KENTO Elec | I36: C2286 | J36: 5889200 | K36: =IF(ISNUMBER(J36),INT(J36/C36),0) | L36: 0.0036 | M36: LOW | N36: Stock fine; 2nd/3rd checked. | P36: 19-217/R6C-AL1M2VY/6T (EVERLIGHT) | Q36: C2986060 | R36: 3778500 | S36: EQ | T36: Everlight 19-217/R6C red | U36: 19-217/R6C-P1Q2/6T (EVERLIGHT) | V36: C2986061 | W36: 64200 | X36: EQ | Y36: Everlight 19-217/R6C-P1Q2 red | Z36: =IF(ISNUMBER(J36),IF(J36>=100*C36,1,0),0)+IF(ISNUMBER(R36),IF(R36>=100*C36,1,0),0)+IF(ISNUMBER(W36),IF(W36>=100*C36,1,0),0)
A37: 25 | B37: D7 | C37: 1 | D37: 1N4148W | E37: D_SOD-123 | F37: Standard (SOD-123) | G37: 1N4148W | H37: ST(Semtech) | I37: C81598 | J37: 2881050 | K37: =IF(ISNUMBER(J37),INT(J37/C37),0) | L37: 0.0061 | M37: LOW | N37: Stock fine; 2nd/3rd checked. | P37: 1N4448W (ST(Semtech)) | Q37: C108428 | R37: 1400 | S37: EQ | T37: 1N4448W 80 V SOD-123 | Y37: none in stock on LCSC | Z37: =IF(ISNUMBER(J37),IF(J37>=100*C37,1,0),0)+IF(ISNUMBER(R37),IF(R37>=100*C37,1,0),0)+IF(ISNUMBER(W37),IF(W37>=100*C37,1,0),0)
A38: 27 | B38: FB1 | C38: 1 | D38: BLM18KG601SN1D | E38: L_0603_1608Metric | F38: Standard (0603 bead) | G38: BLM18KG601SN1D | H38: muRata | I38: C85833 | J38: 806800 | K38: =IF(ISNUMBER(J38),INT(J38/C38),0) | L38: 0.0093 | M38: LOW | N38: Stock fine; 2nd/3rd checked. | P38: BLM18KG601SH1D (muRata) | Q38: C710379 | R38: 21960 | S38: EQ | T38: Murata BLM18KG601SH1D 600R 1.3 A | Y38: none in stock on LCSC | Z38: =IF(ISNUMBER(J38),IF(J38>=100*C38,1,0),0)+IF(ISNUMBER(R38),IF(R38>=100*C38,1,0),0)+IF(ISNUMBER(W38),IF(W38>=100*C38,1,0),0)
A39: 29 | B39: L2,L3 | C39: 2 | D39: FNR5040S470MT | E39: L_Sunlord_SWPA5040S | F39: De-facto standard (many makers) (5040 shielded) | G39: FNR5040S470MT | H39: cjiang | I39: C167974 | J39: 35940 | K39: =IF(ISNUMBER(J39),INT(J39/C39),0) | L39: 0.0455 | M39: LOW | N39: Stock fine; 2nd/3rd checked. | P39: ANR5040T470M (APV) | Q39: C7427133 | R39: 7940 | S39: CHK | T39: APV ANR5040T470M 47 uH 1.3 A sat - no datasheet on LCSC; 5040 body | Y39: none in stock on LCSC | Z39: =IF(ISNUMBER(J39),IF(J39>=100*C39,1,0),0)+IF(ISNUMBER(R39),IF(R39>=100*C39,1,0),0)+IF(ISNUMBER(W39),IF(W39>=100*C39,1,0),0)
A40: 31 | B40: Q2,Q3,Q5,Q6 | C40: 4 | D40: NCEP068N10G | E40: TDSON-8-1 | F40: Standard (DFN5x6 / PowerPAK SO-8) | G40: NCEP068N10G | H40: NCE | I40: C503061 | J40: 7577 | K40: =IF(ISNUMBER(J40),INT(J40/C40),0) | L40: 0.6372 | M40: LOW | N40: Stock fine; 2nd/3rd checked. | P40: NCEP095N10AG (NCE) | Q40: C2686677 | R40: 645 | S40: DS | T40: NCE NCEP095N10AG 100 V 12 mOhm, Qg 54 nC | U40: NCEP0160AG (NCE) | V40: C503012 | W40: 38 | X40: EQ | Y40: previous primary (low / no stock) | Z40: =IF(ISNUMBER(J40),IF(J40>=100*C40,1,0),0)+IF(ISNUMBER(R40),IF(R40>=100*C40,1,0),0)+IF(ISNUMBER(W40),IF(W40>=100*C40,1,0),0)
A41: 32 | B41: Q7,Q8 | C41: 2 | D41: BSC160N15NS5 | E41: TDSON-8-1 | F41: Standard (DFN5x6 / SuperSO8) | G41: BSC160N15NS5 | H41: Infineon | I41: C459172 | J41: 4771 | K41: =IF(ISNUMBER(J41),INT(J41/C41),0) | L41: 0.5455 | M41: LOW | N41: Stock fine; 2nd/3rd checked. | P41: SP015N13GHNK (Siliup) | Q41: C22466810 | R41: 465 | S41: DS | T41: Siliup SP015N13GHNK 150 V 13 mOhm, Qg 30 nC (primary 19 nC) - fine for UCC27524 | U41: LN7910DT1WG (LRC) | V41: C2936692 | W41: 1461 | X41: CHK | Y41: LRC LN7910DT1WG 150 V 15 mOhm - Qg not readable in the datasheet text | Z41: =IF(ISNUMBER(J41),IF(J41>=100*C41,1,0),0)+IF(ISNUMBER(R41),IF(R41>=100*C41,1,0),0)+IF(ISNUMBER(W41),IF(W41>=100*C41,1,0),0)
...

Sheet Spec check findings
A1: Line | B1: Finding | C1: Result
A2: U12 3rd | B2: YLPTEC ISO7742N0-Y (old 3rd source) is the NARROW SOIC-16 body | C2: Won't fit SOIC-16W. Replaced by ISO7742W0-Y (wide, default-low).
A3: U11 3rd | B3: Maxinmicro MX27524S: pin order could not be confirmed from its datasheet | C3: Dropped. TI UCC27524ADR + UMW UCC27524DR (stated pin-to-pin).
A4: U15/17/18 | B4: TPV331S5 / HT331 are push-pull clones with unconfirmed pinout | C4: Replaced by 3PEAK LMV331X-S5TR and ST LMV331ILT (open-drain, same pinout).
A5: U16/U22 | B5: TL431 SOT-23 pinout differs between makers. Board: pin1 = cathode, pin2 = REF (TI DBZ) | C5: U22 must use a 1=K / 2=REF part: TI, UMW, Nexperia normal pinning, HGSEMI. MSKSEMI (no pin numbers) dropped. U16 has pins 1+2 tied so any TL431 works.
A6: TH1 | B6: FH CMFB103F3950FANT (old 2nd) is 0805 | C6: Won't fit the 0603 pads. Replaced by two 0603 10k 1 % B3950 parts.
A7: CR1-CR6 | B7: CCTC / HRE 'M3L' 100 nF 1206 caps show no dielectric - not confirmed C0G | C7: Resonant caps need C0G. Replaced by Murata GRM31C5C2A104JA01L / TDK C3216C0G2A104JT000E.
A8: L1 | B8: SOREDE SRYH.1770 (old 3rd) saturates at 16 A vs 23 A design | C8: Dropped. Shun Xiang Nuo SMMS1770-220M and Sunltech SLO1770C (both 23 A sat). Sunltech land checked: fits.
A9: L2/L3 | B9: APV ANR5040 has no datasheet on LCSC | C9: New primary cjiang FNR5040S470MT: recommended land 1.4 x 4.2 / gap 2.3 = our footprint exactly.
A10: RS1 | B10: Alloy shunt land pattern vs standard R_2512 footprint | C10: HoJLR2512 terminations 0.9 mm sit fully on our pads (2.35-3.58 mm from centre). OK.
A11: SW1 | B11: SHOU HAN TPGT land: 1.1 x 2.2 mm pads, rows 6.6 / 11 mm | C11: Matches our footprint (1.12 x 2.44, rows 6.16 / 10.74).
A12: Q1/Q4 | B12: NCE alternates have Qg 54-60 nC vs 26 nC | C12: Pin-compatible DFN5x6; usable but more switching loss in the hard-switched FETs - bench check.
... A17: C82 | B17: BOM had X7R on the ramp cap | C17: KEMET C0G 47 nF (25 V, node < 5 V).

Sheet PCB reserve
A1: Part | B1: Why | C1: What to add (DNP on the normal build) | D1: Space | E1: Where | F1: Status
A2: T2 PA3855.006NLT | B2: Single maker (Pulse), 102 pcs at LCSC | C2: 3 x 0805 0R jumpers on the secondary: A = pin10->FLY_SA, B = pin6->GND, C = pin6->pin10. Normal (.006): fit A+B. Backup (.005NLT, secondaries in series): fit C only. | D2: ~6 x 4 mm | E2: Free 10 x 8 mm area right of T2 pins 6-10 (x 79.5-89.5, y 46-54) | F2: Waiting for your OK
A3: U9 CA-IS3062VW | B3: Single maker (Chipanalog), integrated isolated DC-DC | C3: 1 x 0402 0R to select U9 pin 1 = +5V (CA-IS3062) or +3V3 (ISO1042DW); B0505S-1WR3 isolated 5 V SIP-4 module + 2 caps feeding VISO. | D3: ~14 x 10 mm + one 0402 | E3: Free area straddling the isolation gap directly above U9 (x 128-142, y 64-74) | F3: Waiting for your OK (module pin spacing vs 4 mm gap to confirm)
